Traceback (most recent call last):
  File "C:\Users\Analista BI\miniconda3\Lib\site-packages\jupyter_cache\executors\utils.py", line 58, in single_nb_execution
    executenb(
  File "C:\Users\Analista BI\miniconda3\Lib\site-packages\nbclient\client.py", line 1305, in execute
    return NotebookClient(nb=nb, resources=resources, km=km, **kwargs).execute()
           ^^^^^^^^^^^^^^^^^^^^^^^^^^^^^^^^^^^^^^^^^^^^^^^^^^^^^^^^^^^^^^^^^^^^^
  File "C:\Users\Analista BI\miniconda3\Lib\site-packages\jupyter_core\utils\__init__.py", line 166, in wrapped
    return loop.run_until_complete(inner)
           ^^^^^^^^^^^^^^^^^^^^^^^^^^^^^^
  File "C:\Users\Analista BI\miniconda3\Lib\asyncio\base_events.py", line 653, in run_until_complete
    return future.result()
           ^^^^^^^^^^^^^^^
  File "C:\Users\Analista BI\miniconda3\Lib\site-packages\nbclient\client.py", line 705, in async_execute
    await self.async_execute_cell(
  File "C:\Users\Analista BI\miniconda3\Lib\site-packages\nbclient\client.py", line 1058, in async_execute_cell
    await self._check_raise_for_error(cell, cell_index, exec_reply)
  File "C:\Users\Analista BI\miniconda3\Lib\site-packages\nbclient\client.py", line 914, in _check_raise_for_error
    raise CellExecutionError.from_cell_and_msg(cell, exec_reply_content)
nbclient.exceptions.CellExecutionError: An error occurred while executing the following cell:
------------------
# Tu clave de API de Google
API_KEY = "#####"

# Inicializar cliente de Google Maps
gmaps = googlemaps.Client(key=API_KEY)

------------------


[1;31m---------------------------------------------------------------------------[0m
[1;31mValueError[0m                                Traceback (most recent call last)
Cell [1;32mIn[2], line 5[0m
[0;32m      2[0m API_KEY [38;5;241m=[39m [38;5;124m"[39m[38;5;124m#####[39m[38;5;124m"[39m
[0;32m      4[0m [38;5;66;03m# Inicializar cliente de Google Maps[39;00m
[1;32m----> 5[0m gmaps [38;5;241m=[39m [43mgooglemaps[49m[38;5;241;43m.[39;49m[43mClient[49m[43m([49m[43mkey[49m[38;5;241;43m=[39;49m[43mAPI_KEY[49m[43m)[49m

File [1;32m~\miniconda3\Lib\site-packages\googlemaps\client.py:144[0m, in [0;36mClient.__init__[1;34m(self, key, client_id, client_secret, timeout, connect_timeout, read_timeout, retry_timeout, requests_kwargs, queries_per_second, queries_per_minute, channel, retry_over_query_limit, experience_id, requests_session, base_url)[0m
[0;32m    140[0m     [38;5;28;01mraise[39;00m [38;5;167;01mValueError[39;00m([38;5;124m"[39m[38;5;124mMust provide API key or enterprise credentials [39m[38;5;124m"[39m
[0;32m    141[0m                      [38;5;124m"[39m[38;5;124mwhen creating client.[39m[38;5;124m"[39m)
[0;32m    143[0m [38;5;28;01mif[39;00m key [38;5;129;01mand[39;00m [38;5;129;01mnot[39;00m key[38;5;241m.[39mstartswith([38;5;124m"[39m[38;5;124mAIza[39m[38;5;124m"[39m):
[1;32m--> 144[0m     [38;5;28;01mraise[39;00m [38;5;167;01mValueError[39;00m([38;5;124m"[39m[38;5;124mInvalid API key provided.[39m[38;5;124m"[39m)
[0;32m    146[0m [38;5;28;01mif[39;00m channel:
[0;32m    147[0m     [38;5;28;01mif[39;00m [38;5;129;01mnot[39;00m re[38;5;241m.[39mmatch([38;5;124m"[39m[38;5;124m^[a-zA-Z0-9._-]*$[39m[38;5;124m"[39m, channel):

[1;31mValueError[0m: Invalid API key provided.

